ERROR 2025-01-06 18:08:35,236 log Internal Server Error: /admin/salons/salon/2/change/
Traceback (most recent call last):
  File "C:\Reservon\Reservon\venv\Lib\site-packages\django\db\backends\utils.py", line 105, in _execute
    return self.cursor.execute(sql, params)
           ^^^^^^^^^^^^^^^^^^^^^^^^^^^^^^^^
  File "C:\Reservon\Reservon\venv\Lib\site-packages\django\db\backends\sqlite3\base.py", line 354, in execute
    return super().execute(query, params)
           ^^^^^^^^^^^^^^^^^^^^^^^^^^^^^^
sqlite3.OperationalError: no such table: salons_historicalsalon

The above exception was the direct cause of the following exception:

Traceback (most recent call last):
  File "C:\Reservon\Reservon\venv\Lib\site-packages\django\core\handlers\exception.py", line 55, in inner
    response = get_response(request)
               ^^^^^^^^^^^^^^^^^^^^^
  File "C:\Reservon\Reservon\venv\Lib\site-packages\django\core\handlers\base.py", line 197, in _get_response
    response = wrapped_callback(request, *callback_args, **callback_kwargs)
               ^^^^^^^^^^^^^^^^^^^^^^^^^^^^^^^^^^^^^^^^^^^^^^^^^^^^^^^^^^^^
  File "C:\Reservon\Reservon\venv\Lib\site-packages\django\contrib\admin\options.py", line 718, in wrapper
    return self.admin_site.admin_view(view)(*args, **kwargs)
           ^^^^^^^^^^^^^^^^^^^^^^^^^^^^^^^^^^^^^^^^^^^^^^^^^
  File "C:\Reservon\Reservon\venv\Lib\site-packages\django\utils\decorators.py", line 188, in _view_wrapper
    result = _process_exception(request, e)
             ^^^^^^^^^^^^^^^^^^^^^^^^^^^^^^
  File "C:\Reservon\Reservon\venv\Lib\site-packages\django\utils\decorators.py", line 186, in _view_wrapper
    response = view_func(request, *args, **kwargs)
               ^^^^^^^^^^^^^^^^^^^^^^^^^^^^^^^^^^^
  File "C:\Reservon\Reservon\venv\Lib\site-packages\django\views\decorators\cache.py", line 80, in _view_wrapper
    response = view_func(request, *args, **kwargs)
               ^^^^^^^^^^^^^^^^^^^^^^^^^^^^^^^^^^^
  File "C:\Reservon\Reservon\venv\Lib\site-packages\django\contrib\admin\sites.py", line 241, in inner
    return view(request, *args, **kwargs)
           ^^^^^^^^^^^^^^^^^^^^^^^^^^^^^^
  File "C:\Reservon\Reservon\venv\Lib\site-packages\django\contrib\admin\options.py", line 1964, in change_view
    return self.changeform_view(request, object_id, form_url, extra_context)
           ^^^^^^^^^^^^^^^^^^^^^^^^^^^^^^^^^^^^^^^^^^^^^^^^^^^^^^^^^^^^^^^^^
  File "C:\Reservon\Reservon\venv\Lib\site-packages\django\utils\decorators.py", line 48, in _wrapper
    return bound_method(*args, **kwargs)
           ^^^^^^^^^^^^^^^^^^^^^^^^^^^^^
  File "C:\Reservon\Reservon\venv\Lib\site-packages\django\utils\decorators.py", line 188, in _view_wrapper
    result = _process_exception(request, e)
             ^^^^^^^^^^^^^^^^^^^^^^^^^^^^^^
  File "C:\Reservon\Reservon\venv\Lib\site-packages\django\utils\decorators.py", line 186, in _view_wrapper
    response = view_func(request, *args, **kwargs)
               ^^^^^^^^^^^^^^^^^^^^^^^^^^^^^^^^^^^
  File "C:\Reservon\Reservon\venv\Lib\site-packages\django\contrib\admin\options.py", line 1820, in changeform_view
    return self._changeform_view(request, object_id, form_url, extra_context)
           ^^^^^^^^^^^^^^^^^^^^^^^^^^^^^^^^^^^^^^^^^^^^^^^^^^^^^^^^^^^^^^^^^^
  File "C:\Reservon\Reservon\venv\Lib\site-packages\django\contrib\admin\options.py", line 1871, in _changeform_view
    self.save_model(request, new_object, form, not add)
  File "C:\Reservon\Reservon\venv\Lib\site-packages\django\contrib\admin\options.py", line 1294, in save_model
    obj.save()
  File "C:\Reservon\Reservon\venv\Lib\site-packages\django\db\models\base.py", line 891, in save
    self.save_base(
  File "C:\Reservon\Reservon\venv\Lib\site-packages\django\db\models\base.py", line 1012, in save_base
    post_save.send(
  File "C:\Reservon\Reservon\venv\Lib\site-packages\django\dispatch\dispatcher.py", line 189, in send
    response = receiver(signal=self, sender=sender, **named)
               ^^^^^^^^^^^^^^^^^^^^^^^^^^^^^^^^^^^^^^^^^^^^^
  File "C:\Reservon\Reservon\venv\Lib\site-packages\simple_history\models.py", line 657, in post_save
    self.create_historical_record(instance, created and "+" or "~", using=using)
  File "C:\Reservon\Reservon\venv\Lib\site-packages\simple_history\models.py", line 758, in create_historical_record
    history_instance.save(using=using)
  File "C:\Reservon\Reservon\venv\Lib\site-packages\django\db\models\base.py", line 891, in save
    self.save_base(
  File "C:\Reservon\Reservon\venv\Lib\site-packages\django\db\models\base.py", line 997, in save_base
    updated = self._save_table(
              ^^^^^^^^^^^^^^^^^
  File "C:\Reservon\Reservon\venv\Lib\site-packages\django\db\models\base.py", line 1160, in _save_table
    results = self._do_insert(
              ^^^^^^^^^^^^^^^^
  File "C:\Reservon\Reservon\venv\Lib\site-packages\django\db\models\base.py", line 1201, in _do_insert
    return manager._insert(
           ^^^^^^^^^^^^^^^^
  File "C:\Reservon\Reservon\venv\Lib\site-packages\django\db\models\manager.py", line 87, in manager_method
    return getattr(self.get_queryset(), name)(*args, **kwargs)
           ^^^^^^^^^^^^^^^^^^^^^^^^^^^^^^^^^^^^^^^^^^^^^^^^^^^
  File "C:\Reservon\Reservon\venv\Lib\site-packages\django\db\models\query.py", line 1847, in _insert
    return query.get_compiler(using=using).execute_sql(returning_fields)
           ^^^^^^^^^^^^^^^^^^^^^^^^^^^^^^^^^^^^^^^^^^^^^^^^^^^^^^^^^^^^^
  File "C:\Reservon\Reservon\venv\Lib\site-packages\django\db\models\sql\compiler.py", line 1836, in execute_sql
    cursor.execute(sql, params)
  File "C:\Reservon\Reservon\venv\Lib\site-packages\debug_toolbar\panels\sql\tracking.py", line 235, in execute
    return self._record(super().execute, sql, params)
           ^^^^^^^^^^^^^^^^^^^^^^^^^^^^^^^^^^^^^^^^^^
  File "C:\Reservon\Reservon\venv\Lib\site-packages\debug_toolbar\panels\sql\tracking.py", line 160, in _record
    return method(sql, params)
           ^^^^^^^^^^^^^^^^^^^
  File "C:\Reservon\Reservon\venv\Lib\site-packages\django\db\backends\utils.py", line 122, in execute
    return super().execute(sql, params)
           ^^^^^^^^^^^^^^^^^^^^^^^^^^^^
  File "C:\Reservon\Reservon\venv\Lib\site-packages\django\db\backends\utils.py", line 79, in execute
    return self._execute_with_wrappers(
           ^^^^^^^^^^^^^^^^^^^^^^^^^^^^
  File "C:\Reservon\Reservon\venv\Lib\site-packages\django\db\backends\utils.py", line 92, in _execute_with_wrappers
    return executor(sql, params, many, context)
           ^^^^^^^^^^^^^^^^^^^^^^^^^^^^^^^^^^^^
  File "C:\Reservon\Reservon\venv\Lib\site-packages\django\db\backends\utils.py", line 100, in _execute
    with self.db.wrap_database_errors:
         ^^^^^^^^^^^^^^^^^^^^^^^^^^^^
  File "C:\Reservon\Reservon\venv\Lib\site-packages\django\db\utils.py", line 91, in __exit__
    raise dj_exc_value.with_traceback(traceback) from exc_value
  File "C:\Reservon\Reservon\venv\Lib\site-packages\django\db\backends\utils.py", line 105, in _execute
    return self.cursor.execute(sql, params)
           ^^^^^^^^^^^^^^^^^^^^^^^^^^^^^^^^
  File "C:\Reservon\Reservon\venv\Lib\site-packages\django\db\backends\sqlite3\base.py", line 354, in execute
    return super().execute(query, params)
           ^^^^^^^^^^^^^^^^^^^^^^^^^^^^^^
django.db.utils.OperationalError: no such table: salons_historicalsalon
ERROR 2025-01-11 18:51:11,259 log Internal Server Error: /auth/login
Traceback (most recent call last):
  File "C:\Reservon\Reservon\venv\Lib\site-packages\django\core\handlers\exception.py", line 55, in inner
    response = get_response(request)
               ^^^^^^^^^^^^^^^^^^^^^
  File "C:\Reservon\Reservon\venv\Lib\site-packages\django\utils\deprecation.py", line 131, in __call__
    response = self.process_response(request, response)
               ^^^^^^^^^^^^^^^^^^^^^^^^^^^^^^^^^^^^^^^^
  File "C:\Reservon\Reservon\venv\Lib\site-packages\django\middleware\common.py", line 108, in process_response
    return self.response_redirect_class(self.get_full_path_with_slash(request))
                                        ^^^^^^^^^^^^^^^^^^^^^^^^^^^^^^^^^^^^^^
  File "C:\Reservon\Reservon\venv\Lib\site-packages\django\middleware\common.py", line 87, in get_full_path_with_slash
    raise RuntimeError(
RuntimeError: You called this URL via POST, but the URL doesn't end in a slash and you have APPEND_SLASH set. Django can't redirect to the slash URL while maintaining POST data. Change your form to point to 127.0.0.1:8000/auth/login/ (note the trailing slash), or set APPEND_SLASH=False in your Django settings.
ERROR 2025-01-11 18:51:41,896 log Internal Server Error: /auth/login
Traceback (most recent call last):
  File "C:\Reservon\Reservon\venv\Lib\site-packages\django\core\handlers\exception.py", line 55, in inner
    response = get_response(request)
               ^^^^^^^^^^^^^^^^^^^^^
  File "C:\Reservon\Reservon\venv\Lib\site-packages\django\utils\deprecation.py", line 131, in __call__
    response = self.process_response(request, response)
               ^^^^^^^^^^^^^^^^^^^^^^^^^^^^^^^^^^^^^^^^
  File "C:\Reservon\Reservon\venv\Lib\site-packages\django\middleware\common.py", line 108, in process_response
    return self.response_redirect_class(self.get_full_path_with_slash(request))
                                        ^^^^^^^^^^^^^^^^^^^^^^^^^^^^^^^^^^^^^^
  File "C:\Reservon\Reservon\venv\Lib\site-packages\django\middleware\common.py", line 87, in get_full_path_with_slash
    raise RuntimeError(
RuntimeError: You called this URL via POST, but the URL doesn't end in a slash and you have APPEND_SLASH set. Django can't redirect to the slash URL while maintaining POST data. Change your form to point to 127.0.0.1:8000/auth/login/ (note the trailing slash), or set APPEND_SLASH=False in your Django settings.
